Workbook

Sheet 품목별현황 - 상세
B2: ■. 각 품목별 현재 개발 현황(23-04-27 기준)
B3: 품목 | C3: 구분 | D3: 채번 | E3: BOM | F3: 라우팅 | G3: 금형 | H3: 영업PO | I3: 자재PO | J3: 생산PO | K3: 생산 | L3: 품질 | M3: 라벨 | N3: 출하
B4: OCA | C4: 시범운영 | D4: ● | E4: ● | F4: ● | G4: ● | H4: - | I4: ● | J4: ● | K4: ● | L4: ● | M4: X | N4: X
C5: 정상운영 | D5: ● | E5: ● | F5: ● | G5: ● | H5: ▲ | I5: ● | J5: ▲ | K5: ▲ | L5: ▲ | M5: ▲ | N5: X
B6: PL | C6: 시범운영 | D6: ● | E6: ● | F6: ● | G6: - | H6: - | I6: ● | J6: ● | K6: ● | L6: ● | M6: X | N6: X
C7: 정상운영 | D7: ● | E7: ● | F7: ▲ | G7: - | H7: - | I7: ● | J7: X | K7: X | L7: X | M7: X | N7: X
B8: TAPE | C8: 시범운영 | D8: ▲ | E8: ▲ | G8: - | H8: -
C9: 정상운영
B10: SUS | C10: 시범운영 | D10: ● | E10: ● | F10: ● | G10: ● | H10: - | I10: ● | J10: ● | K10: ▲
C11: 정상운영
B12: DECO | C12: 시범운영 | D12: ● | E12: ● | F12: ● | G12: - | H12: - | I12: ● | J12: ● | M12: X | N12: X
C13: 정상운영
B14: PCPMMA | C14: 시범운영 | D14: ▲ | E14: ▲
C15: 정상운영
B16: 선합지 | C16: 시범운영
C17: 정상운영
B21: 12일에 | C21: nitto 방문
B22: 품목 | C22: 구분 | D22: 채번 | E22: BOM | F22: 라우팅 | G22: 금형 | H22: 영업PO | I22: 자재PO | J22: 생산PO | K22: 생산 | L22: 품질 | M22: TRAY (CELL) | N22: Pack label | O22: BOX label | P22: QR | Q22: 출하
B23: OCA | C23: NITTO | D23: ● | E23: ● | F23: ● | G23: ● | H23: X | I23: ● | J23: ● | K23: ● | L23: ● | M23: ▲ | N23: ▲ | O23: ▲ | P23: - | Q23: X
B24: OCA | C24: SDI | D24: ● | E24: ● | F24: ● | G24: ● | H24: X | I24: ● | J24: ● | K24: ● | M24: 45058 | N24: 45058 | O24: 45058
B25: TAPE | C25: 타발
B26: SUS | C26: TAPE
B27: SUS | C27: 조립
B28: PL | C28: 기존라인 | P28: 1차TEST완료
B29: PL | C29: 자동라인
B30: DECO | C30: 삼성
B31: DECO | C31: OPPO
B32: PCPMMA | C32: 삼성
B33: PCPMMA | C33: OPPO
B34: 선합지 | C34: 일반등록
B35: 선합지 | C35: PLC
B36: 선합지 | C36: EDI

Sheet 현황
B2: ■ 전산관련 진행 현황
B3: 1. 전산관련 업무 내용 별 진척현황
B4: 구분 | C4: 총항목 | D4: 예정 | E4: 진행중 | F4: 완료 | G4: 진척율
B5: Flow | C5: =COUNTIF(세부내용!C:C,현황!$B5) -> 21 | D5: =COUNTIFS(세부내용!$C:$C,현황!$B5,세부내용!$D:$D,"X") -> 4 | E5: =COUNTIFS(세부내용!$C:$C,현황!$B5,세부내용!$D:$D,"△") -> 7 | F5: =COUNTIFS(세부내용!$C:$C,현황!$B5,세부내용!$D:$D,"O") -> 10 | G5: =+F5/C5 -> 0.47619048
B6: 개발 | C6: =COUNTIF(세부내용!C:C,현황!$B6) -> 30 | D6: =COUNTIFS(세부내용!$C:$C,현황!$B6,세부내용!$D:$D,"X") -> 5 | E6: =COUNTIFS(세부내용!$C:$C,현황!$B6,세부내용!$D:$D,"△") -> 11 | F6: =COUNTIFS(세부내용!$C:$C,현황!$B6,세부내용!$D:$D,"O") -> 14 | G6: =+F6/C6 -> 0.46666667
B7: 개선 | C7: =COUNTIF(세부내용!C:C,현황!$B7) -> 39 | D7: =COUNTIFS(세부내용!$C:$C,현황!$B7,세부내용!$D:$D,"X") -> 8 | E7: =COUNTIFS(세부내용!$C:$C,현황!$B7,세부내용!$D:$D,"△") -> 6 | F7: =COUNTIFS(세부내용!$C:$C,현황!$B7,세부내용!$D:$D,"O") -> 25 | G7: =+F7/C7 -> 0.64102564 | J7: `
B8: 합계 | C8: =SUM(C5:C7) -> 90 | D8: =SUM(D5:D7) -> 17 | E8: =SUM(E5:E7) -> 24 | F8: =SUM(F5:F7) -> 49 | G8: =+F8/C8 -> 0.54444444
B9: * 개발 / 개선 항목은 운영 진행간 추가 예상
B11: 2. 각 품목별 운영관련 예상일정
B12: 품목 | C12: 기준정보등록 | E12: 시범운영 | G12: 오픈운영 | I12: 비고
B13: OCA | C13: 3월 17일까지 | E13: 3월 20일 부터 | G13: 45059 | I13: 등록 진행 중 - 기존프로그램 버릴시 고객 "C' LOT 제출 예정
B14: PL | C14: 4월 7일까지 | E14: 4월10일 부터 | G14: 45059 | I14: 등록 진행 중
B15: TAPE | C15: 지속등록 중 | E15: 45049 | G15: 45078 | I15: 일부모델부터 진행(DOW)
B16: SUS/UB | C16: 4월 20일까지 | E16: 4월 17일부터 / 5월3일 재진행 | G16: 45096 | I16: 진행 예정
B17: DECO | C17: 45087 | E17: 4월 17일부터 / 5월3일 재진행 | G17: 45131 | I17: B5양산 적용 우선 진행 이후 순차 등록 진행
B18: PCPMMA | C18: 45087 | E18: 45078 | G18: 45108 | I18: - BOM / 라우팅 등록 예정
B19: 선합지 | C19: 45082 | E19: 45139 | G19: 45170 | I19: 개발에 따른 일정은 변경진행(7월까지 구축완료 / 8월 말까지 최종개선)
T20: ㄴ
B21: □ 각 부분별 적용 시점 재 확인
B22: 구분 | C22: 내용 | E22: 비고 | F22: 6월1주 | G22: 6월2주 | H22: 6월3주 | I22: 6월4주 | J22: 7월1주 | K22: 7월2주 | L22: 7월3주 | M22: 7월4주 | N22: 8월1주 | O22: 8월2주 | P22: 8월3주 | Q22: 8월4주 | R22: 8월5주 | S22: 9월1주 | T22: 9월2주 | U22: 9월3주 | V22: 9월4주 | W22: 10월1주 | X22: 10월2주 | Y22: 10월3주 | Z22: 10월4주
B23: QV | C23: CODE등록 | F23: 지속 등록 진행
C24: BOM등록 | F24: 신규OCA TAPE, | G24: 신규OCA TAPE,
C25: 라우팅등록 | F25: 신규OCA TAPE, | G25: 신규OCA TAPE, | N25: PWA TEST | S25: PWA 1차오픈
C26: 자품목투입설정 | F26: 신규OCA TAPE, | G26: 신규OCA TAPE, | H26: TAPE | I26: TAPE | J26: TAPE | N26: PWA TEST | S26: PWA 1차오픈
C27: 수주등록 | F27: 신규OCA TAPE, | G27: 신규OCA TAPE, | H27: TAPE | I27: TAPE | J27: TAPE | O27: PWA TEST | S27: PWA 1차오픈
C28: 출하의뢰등록 | F28: 신규OCA TAPE, | O28: PWA TEST | S28: PWA 1차오픈
C29: 제조오더등록 | F29: 신규OCA TAPE, | O29: PWA TEST | S29: PWA 1차오픈
C30: 재고일괄생성 | F30: 신규OCA TAPE, | N30: PWA TEST | S30: PWA 1차오픈
C31: 재고실사 | I31: 일부진행 | M31: PWA제외 전수진행
C32: 단독적용 | S32: PWA,PL제외 전용시작 | W32: 전수전용시작
B33: YP | C33: CODE등록 | F33: 지속 등록 예정
C34: BOM등록 | G34: UB, SUS | H34: PCPMMA | I34: PCPMMA | J34: PCPMMA | K34: DECO | L34: DECO | M34: DECO
C35: 라우팅등록 | G35: UB, SUS | H35: PCPMMA | I35: PCPMMA | J35: PCPMMA | K35: DECO | L35: DECO | M35: DECO
C36: 자품목투입설정 | G36: UB, SUS | H36: PCPMMA | I36: PCPMMA | J36: PCPMMA | K36: DECO | L36: DECO | M36: DECO
C37: 수주등록 | G37: UB, SUS | H37: PCPMMA | I37: PCPMMA | J37: PCPMMA | K37: DECO | L37: DECO | M37: DECO
C38: 출하의뢰등록 | H38: UB, SUS시작 | J38: PCPMMA시작 | M38: DECO시작
C39: 제조오더등록 | H39: UB, SUS시작 | J39: PCPMMA시작 | M39: DECO시작
C40: 재고일괄생성 | H40: UB, SUS | I40: PCPMMA | L40: DECO
C41: 재고실사 | I41: 일부진행 | M41: 일부진행 | S41: 전수진행
C42: 단독적용 | W42: 전수전용시작
...

Sheet -
B2: ■ 진행간 각 문제점요약
B3: No. | C3: 부서 | D3: 주제 | E3: 내용 | N3: 업무 진행 방향 | W3: 해결 여부
B4: 1 | C4: 구매 | D4: 발주 | E4: . 구매 발주 진행시 다중 발주가 안되어 제품군별 개별 발주 및 업체별 개별 발주 진행 해야함 -> 개별 각 제품군별 등록 인한 업무 지연 | N4: 1. 다중업체 /다중제품군/다중품목의 발주 진행하는 화면 개발예정 1) 일괄 다중 등록인한 오 등록 부분은 프로세스 수립 필요 2) 화면 구상은 완료 | W4: 1. 내부 미팅 후 업체 미팅예정
B5: 2 | C5: 구매 | D5: 입고 | E5: . 입고시 개별 lot별 입고하는데 업무시간 지연 발생 -> 개별 LOT별 한건 한건 등록 진행 중인 상황 -> 임시대책으로 통 입고 후 Lot분배 진행 예정 | N5: 1. 오더 內 Lot별 분할입고, 다중품목 입고를 지원 할 수있도록 화면 개발 예정 1) 화면 구상은 완료 | W5: 1. 내부 미팅 후 업체 미팅예정
B6: 3 | C6: 구매 | D6: 입고 | E6: . BL발주 입고에 대한 입고시 대응 방안수립필요 -> BL입고시 입고 품목이 상이하는경우 발생(1000폭 요청 500폭입고시) -> 다중 BL 입고시 | N6: 1. BL관련 상황별 및 필요 화면 접수예정 1) 추가 예상되어지는 여러 상황에 대한 list 접수 개선방향 접수하여 개발방향 수립 예정 2) 문제사항에 대한 해결법 구상 | W6: 1. 내부 미팅 후 업체 미팅예정
B7: 4 | C7: 구매 | D7: 슬리팅 | E7: . 슬리팅 오더시 여러 상황에 대한 대응이 어려움 -> 각 CR폭별 슬리팅PO수립시 조합의 어려움 (CR조합시 슬리팅시 PO개별 등록 및 관리로 인한 번거로움) -> MR전체 소진이 아닌 일부 폭 슬리팅시 추가 계산의 어려움 (1000폭 중 500폭만 슬리팅 후 잔여 폭에 대한 품목 변황이 필요함) | N7: 1. 슬리팅 관련 화면 별도 구성 1) 슬리팅 발주시 MR기준 다중오더 구성 2) 일부 폭 슬리팅시 MR 품목 변환 기능 가능여부 확인필요 3) CR품목에 대한 코드 자동생성 기능 추가 가능여부 타진 | W7: 1. 내부 미팅 후 업체 미팅예정
B8: 5 | C8: 전체 | D8: 재고조사 | E8: . 일부공정 수기 조사 및 엑셀 파일 정리진행 -> 일부 생산 / 제품창고 외 수기=전산 비교 진행 | N8: 1. 전체 전산 재고화 및 재고관리가능여부 체크 필요 1) 수불에대한 관리 기준 변경으로 확인 필요. 2) 관리도 수준 기준\ 필요 | W8: 1. 내부 미팅 후 업체 미팅예정
B9: 6 | C9: 전체 | D9: 소요량 | E9: . 투입 Lot 기준의 소요량 계산으로 인해 후공정 자재 추가 loss발생 예정 -> 과투입처리로 인한 재고 수량 상이 발생 에상 -> 현재 초 공정 기준으로 투입 수량 계산 되어짐 | N9: 1. 각 공정별 진행 수량으로 계산 되어 질 수있는지 확인 필요 1) I/F 진행 시 ERP / MES 모두 확인 필요 2) 공정별 계산으로 인한 ERP 오류 발생 예상상황 확인 진행 | W9: 1. 내부 개선 작업 진행 에정
B10: 7 | C10: 전체 | D10: 소요량 | E10: . 소요량 계산 소수점 단위 관리에 대한 방안 필요 -> 현재 소수점 6자리까지만 관리 진행 (그 이상되는 경우 관리단위 변경하여 대응 진행) -> I/F간 오류를 막기위해 소수점 4자리 반올림하여 진행 | N10: 1. 관리 되는 소수점 단위 변경 가능여부 타진 중 1) 소모량 적은자재의 관리여부 확인 필요 - 추후 일괄 투입 or 미관리 처리 등의 다른 프로세스 진행 여부 확인 필요 2) 관리되어야 하는 소수점 단위 설정 필요 | W10: 1. 업체 미팅예쩡
B11: 8 | C11: 생산/품질 | D11: 인수인계 | E11: . 현재 인수 인계 미 활성화 중 -> 각 공정운영에 초점에 맞춰 현재는 실적 등록 위주로 작업 진행 중 . 출하검사 이후 PACK 제품창고 인수인계 관련 내용 정리 필요 -> 이 부분은 필수 적으로 적용 진행 필요(재고실사 진행을 위함) | N11: 1. 인수인계 진행 품목 설정 필요(전체품목 활성화 필요 예상) 1) 품목별 설정 기능있으며 전체 활성화로 재고 공정별 확인 및 누락 lot추적성 증대필요 2) 재고 확인의 용이함 3) 공정재고실사 기능 활성화를 위함 2. 기능은 구현 진행 완료 - 사용에 대한 의견 수립필요 | W11: 1. 내부 개선 작업 및 적용 TEST진행예정
B12: 9 | C12: YP,QV | D12: 인프라 및 관리도 | E12: . 전산 필수 항목으로 인식이 안되어 있어 접목에 어려움이 있음 - (2중 등록 상황) . 다중 설비 및 자재 투입 등으로 관리진행시 추가 인프라 구축이 필요함 | N12: 1. 관리 수준의 설정 필요 1) 관리수준에 따른 추가 인프라 구축 범위 설정진행 예정 2) 구축현황에 대한 내용은 정리 진행 중 2. 활성화 운영을 위한 필요사항 추가 체크 1) 전산 실적등록자 별도 운영여부 2) 자재관리 관련 공정별 필요여부 - 실재고 체크 및 정리 진행 인력 확인 진행 3) 전산 등록을 위한 방향 수립 필요 | W12: -
B13: 10 | C13: - | D13: 선합지 | E13: . 기 공유 된 계획대비 일정 지연(2차공유 - 6월 / 현재 기준 - 9월 사용예상) -> 기존 프로세스 방향에 대한 내용 확인 미진하여 재 수립 진행 -> 추가 화면 및 내용으로 개발 기간 연장 -> 고객 토큰 발행 지연으로 인해 연동 내용 확인 지연 | N13: 1. 개발인력 추가 투입을 통한 일정 단축 가능여부 확인 2. 고객 토큰 발행 일정 재확인 필요(현재 기준 6월 중 답변 접수 예정) 3. 조회 화면은 자체 개발 가능 항목 별도 설정 하여 일정 단축 진행 4. 일부 기능 활성화시 선 진행을 통한 문제점 사전 파악 진행
B14: 11 | C14: 전산 | D14: I/F | E14: . 실적 I/F 관련 잦은 오류 발생으로 인해 근본적인 해결 방안 수립 필요 . I/F TIME 지연으로 인한 재고 오류 발생 | N14: 1. ERP / MES간 재고 처리에 대한 별도 table or 계산 table 방안 확인진행 1) I/F 지연 TIME으로 인한 오 투입 가능여부 제어 필요 - 일부 개선 진행 2) I/F 줄일 수있는 방법 확인 진행 2. I/F 진행 전 별도 확인 가능한 방법 확인(각 DB별 사전 확인 방법)
B15: 12 | C15: - | D15: AOI 관련 | E15: . NPI 구역기준 외부로 이미지 파일 이동 안되는 것으로 1차 확인 . 전체 일정 지연으로 전산연동 관련 일정도 연기 | N15: 1. SDV, SDC NPI 관련 담당다 통한 2차 확인 진행 - 국내 영업팀 통한 추가 확인 진행 2. 자체 TEST 기간 동안 업체 S/W 인력들을 통한 자투리 작업 우선 진행하여 일부 일정 단축 진행 추진

Sheet 세부내용
A1: 2
B2: ■ 신규 ERP / ME전산 운영을 위한 일정
B3: 1. 진행 예정 세부사항
B4: No. | C4: 대분류 | D4: 완료여부 | E4: 부서 | F4: 내용 | G4: 구분 | H4: 상세내용 | U4: 우선순위 | V4: 일정일자 및 완료일자 | W4: 일정
W5: 3월3주 | X5: 3월4주 | Y5: 3월5주 | Z5: 4월1주 | AA5: 4월2주 | AB5: 4월3주 | AC5: 4월4주 | AD5: 5월1주 | AE5: 5월2주 | AF5: 5월3주 | AG5: 5월4주 | AH5: 5월5주 | AI5: 6월1주 | AJ5: 6월2주 | AK5: 6월3주 | AL5: 6월4주 | AM5: 7월1주 | AN5: 7월2주 | AO5: 7월3주 | AP5: 7월4주 | AQ5: 7월5주 | AR5: 8월1주 | AS5: 8월2주 | AT5: 8월3주 | AU5: 8월4주 | AV5: 9월1주 | AW5: 9월2주 | AX5: 9월3주 | AY5: 9월4주 | AZ5: 10월1주 | BA5: 10월2주 | BB5: 10월3주 | BC5: 10월4주 | BD5: 10월4주
B6: 1 | C6: FLOW | D6: O | E6: 생산 | F6: 사전점검 | H6: 국내향 모델로 사전점검 진행(SDI향 CODE ~ PACK 라벨 발행까지) | V6: 완료
B7: =+B6+1 -> 2 | C7: FLOW | D7: O | E7: 생산 | F7: 모델선정 | H7: 전산 TEST 가동 예정 모델 선정 진행(생산팀 결정 필요) - 모델 NITTO 2종 선정 진행 | V7: 완료
B8: =+B7+1 -> 3 | C8: FLOW | D8: O | E8: 개발 | F8: OCA | G8: ERP | H8: 선정된 모델의 BOM 등록진행 | V8: 3/17~3/23 | X8: 교육및 등록완료
B9: =+B8+1 -> 4 | C9: FLOW | D9: O | E9: 생산 | F9: OCA | G9: ERP | H9: 라우팅 구성 및 자품목 투입 설정 진행 | V9: 3/17~3/23 | X9: 교육및 등록완료
B10: =+B9+1 -> 5 | C10: FLOW | D10: O | E10: 구매 | F10: OCA | G10: ERP | H10: 전산 자재 발주 및 입고 등록 진행(시범운영) | V10: 3/27~ | X10: 교육완료-입고진행 | Y10: 입고진행
B11: =+B10+1 -> 6 | C11: FLOW | D11: O | E11: 생산 | F11: OCA | G11: ERP | H11: 선 진행 모델 투입 및 생산 실적 등록 진행(시범운영) | V11: 3/27~ | X11: 교육완료-입고진행
B12: =+B11+1 -> 7 | C12: 개발 | D12: O | E12: 생산 | F12: 금형관련 | G12: MES | H12: 금형 모델별 지정사용 진행 (해당 모델에는 지정 모델의 칼 금형만 사용 가능) | V12: 45021 | W12: 개발 중 | X12: 개발 중 | Y12: 개발 중 | Z12: 적용시작
B13: =+B12+1 -> 8 | C13: 개선 | D13: O | E13: 생산 | F13: 금형관련 | G13: ERP | H13: 금형 LOT 라벨 관리 확인 - (금형 라벨 발행 및 관리내역) - 최종 라벨사양은 추가 업데이트 예정 | V13: 45041 | AA13: 개발 중 | AB13: 개발 중 | AC13: 적용
B14: =+B13+1 -> 9 | C14: 개선 | D14: O | E14: 생산 | F14: 금형관련 | G14: MES | H14: 샘플 / 양산 금형 구분 관리 기능 추가 - PINACLE 에 대해서 별도 코드화 하여 진행 | V14: 45016
B15: =+B14+1 -> 10 | C15: 개발 | D15: O | E15: 품질 | F15: 라벨 | G15: ERP/MES | H15: 선 진행 예정모델 기준 라벨 우선 개발 진행(NITTO 우선진행) | V15: 45046 | AA15: 개발진행 | AB15: 개발진행 | AC15: 개발진행 | AD15: 적용
B16: =+B15+1 -> 11 | C16: 개선 | D16: O | E16: 생산 | F16: 실적 | G16: POP | H16: 해당공정 위치로 커서 위치 될 수있도록 | V16: 45016
B17: =+B16+1 -> 12 | C17: 개발 | D17: O | E17: 품질 | F17: 라벨 | G17: MES | H17: 중라벨 관련 개발 필요(nitto 향) - 잔금문제로 인한 일정 delay | V17: 45042
B18: =+B17+1 -> 13 | C18: FLOW | D18: O | E18: 품질 | F18: OCA | G18: ERP/MES | H18: 실적 등록 및 라벨 발행 등록 진행(시범운영) | V18: 실적-3/28, 라벨-4/17 | Y18: 실적등록 | Z18: 실적등록 | AA18: 실적등록 | AB18: 실적등록/ 라벨발행
B19: =+B18+1 -> 14 | C19: FLOW | D19: O | E19: 공통 | F19: PL | G19: ERP/MES | H19: 시범운영(기초 정보 입력 / 모델선정 - 마킹 제외) | V19: 4/5~ | Y19: 준비 | Z19: 등록진행 | AA19: 등록진행 | AB19: 등록진행
B20: =+B19+1 -> 15 | C20: 개발 | D20: O | E20: 구매 | F20: 발주 | G20: ERP | H20: 발주 입력시 Roll 수량 및 m기입시 초량 반영 및 sqm 표시 | U20: 1 | V20: 45029 | X20: 개발중 | Y20: 개발중 | Z20: 개발중 | AA20: 적용
B21: =+B20+1 -> 16 | C21: 개발 | D21: O | E21: 구매 | F21: 발주서 | G21: ERP | H21: 발주서 상 ROLL 및 SQM 표기 진행 필요 - 요청 화면은 정리 진행 | V21: 45029 | X21: 개발중 | Y21: 개발중 | Z21: 개발중 | AA21: 적용
B22: =+B21+1 -> 17 | C22: 개발 | D22: X | E22: 구매 | F22: 입고 | G22: ERP | H22: 한건 발주 다중입고 진행시 입고편의 기능 추가 필요 | V22: 7월 중 | AJ22: 내용정리 | AK22: 내부미팅 | AL22: 업체미팅/방향설정 | AM22: 개발 | AN22: 개발 | AO22: 개발 | AP22: 적용
B23: =+B22+1 -> 18 | C23: 개선 | D23: X | E23: 구매 | F23: 기준정보 | G23: ERP | H23: 구매 최소수량 단위 기입내용 활용 범위 확인 및 적용 필요 | U23: 1 | V23: 7월 중 | AJ23: 내용정리 | AK23: 내부미팅 | AL23: 업체미팅/방향설정 | AM23: 개발 | AN23: 개발 | AO23: 개발 | AP23: 적용
B24: =+B23+1 -> 19 | C24: 개선 | D24: X | E24: 구매 | F24: 구매요청 | G24: ERP | H24: 구매요청사항에 대해 업체 배분완료시 조회 화면에서 제외 및 별도 표기 필요(MRP 사용시) | V24: 7월 중 | AJ24: 내용정리 | AK24: 내부미팅 | AL24: 업체미팅/방향설정 | AM24: 개발 | AN24: 개발 | AO24: 개발 | AP24: 적용
B25: =+B24+1 -> 20 | C25: 개발 | D25: △ | E25: 생산 | F25: 선합지 | G25: MES | H25: PLC관련 연동 확인 | V25: 7월 2주차 | AG25: 연동개발 | AH25: 연동개발 | AI25: 연동개발 | AJ25: 연동개발 | AK25: 개발/간이 TEST | AL25: 28일실연동TEST | AM25: 연동TEST | AN25: 연동TEST
B26: =+B25+1 -> 21 | C26: 개선 | D26: △ | E26: 영업 | F26: 출하 | G26: ERP | H26: 다중 PACK 출하 진행 관련 편의성 향상 - 라벨 완 박스 진행시 자동 라벨 발행 및 포장 단위변경 가능 여부 | U26: 1 | V26: 6월 말 | AK26: 개발 | AL26: 적용
B27: =+B26+1 -> 22 | C27: 개선 | D27: O | E27: 개발 | F27: BOM | G27: ERP | H27: BOM 등록시 BOM의 개취수 확인용 열 추가 진행(개별 수량 입력 후 해당 단위별 개취수 확인진행) | V27: 45023 | Z27: 개발진행 | AA27: 개발진행 | AB27: 적용
B28: =+B27+1 -> 23 | C28: 개선 | D28: O | E28: 영업 | F28: PDA | G28: PDA | H28: 출하 작업시 커서 포인트 위치 고정(연속 등록 작업시) - PDA 조정 | V28: 45056 | AC28: 개발 | AD28: 적용TEST
B29: =+B28+1 -> 24 | C29: FLOW | D29: O | E29: 공통 | F29: DECO, PCPMMA | G29: ERP/MES | H29: 시범운영(기초 정보 입력 / 모델선정 - 마킹 제외) | V29: 45049 | AA29: 준비 | AB29: 등록진행 | AC29: 서비리부트 재준비 | AD29: 등록진행
B30: =+B29+1 -> 25 | C30: FLOW | D30: O | E30: 공통 | F30: SUS | G30: ERP/MES | H30: 시범운영(기초 정보 입력 / 모델선정) | V30: 4월 10일 부터 | AA30: 준비 | AB30: 등록진행 | AC30: 서비리부트 재준비 | AD30: 등록진행
B31: =+B30+1 -> 26 | C31: 개발 | D31: △ | E31: 품질 | F31: 라벨 | G31: ERP/MES | H31: 고객사별 및 모델 라벨 타입 개발 진행 | V31: 45076 | AC31: 개발 | AD31: 개발 | AE31: 개발 | AF31: 개발 | AG31: 개발 | AH31: 개발 | AI31: 개발 | AK31: 개발
B32: =+B31+1 -> 27 | C32: 개발 | D32: △ | E32: 생산 | F32: 선합지 | G32: ERP/MES | H32: 라벨관련 | V32: 7월이전 확보진행 | AL32: 개발
B33: =+B32+1 -> 28 | C33: 개발 | D33: X | E33: 구매 | F33: BL입고 | G33: ERP | H33: BL입고시 다중 PO건에 대해 조회 및 선택 가능하도록 추가로 입고시 변경되는 품목코드에 대해 반영 필요 (필요 그림은 접수 예정) | V33: 7월 1주차 | AK33: 요청그림접수 | AL33: 업체미팅 | AM33: 개발 | AN33: 개발 | AO33: 적용
B34: =+B33+1 -> 29 | C34: 개발 | D34: △ | E34: 품질 | F34: 마킹 | G34: MES | H34: 폴더블용 마킹프로그램 | V34: 차주 중 | W34: SP개발중 | X34: SP개발완료및TEST 견적 접수 요청 | Y34: SP개발완료및TEST 견적 접수 요청 | Z34: 프로그램개발 | AA34: 프로그램개발 | AB34: 프로그램개발 | AC34: 프로그램 1차배포 | AD34: 문제점확인 | AE34: 추가보완 | AF34: 추가보완 | AH34: 추가보완 | AK34: 추가보완 | AL34: 추가보완
B35: =+B34+1 -> 30 | C35: 개발 | D35: O | E35: 품질 | F35: 마킹 | G35: MES | H35: 마킹장비 연동 TEST | V35: 45071 | AE35: 연동TEST | AF35: 연동TEST | AG35: 연동TEST
B36: =+B35+1 -> 31 | C36: 개발 | D36: O | E36: 품질 | F36: 마킹 | G36: MES | H36: DECO DM마킹용 프로그램 | V36: 수동만반영
B37: =+B36+1 -> 32 | C37: 개발 | D37: △ | E37: 생산 | F37: 선합지 | G37: MES | H37: POP프로그램 | V37: 7월말목표 8월 수정완료 | AI37: 수검 | AJ37: 전수검사 | AK37: Autoclave | AL37: 전수검사 | AM37: 반품관련 | AN37: 리웍관련 | AO37: SIQC관련 | AP37: 재포장관련 | AQ37: FULL TEST | AR37: 기능보완 | AS37: 기능보완
B38: =+B37+1 -> 33 | C38: 개발 | D38: △ | E38: 생산 | F38: 선합지 | G38: MES | H38: EDI 관련 확인 | V38: 토큰 미 발행으로 확인필요 | AI38: EDI 환경구축 | AJ38: EDI 환경구축 | AK38: EDI 환경구축 | AL38: EDI 환경구축 | AM38: 연동TEST | AN38: 연동TEST | AO38: 연동TEST | AP38: 연동TEST | AQ38: 연동TEST
B39: =+B38+1 -> 34 | C39: 개선 | D39: △ | E39: 공통 | F39: 레이블 | G39: ERP/MES | H39: 언어 싱크(베트남어 레이블) | V39: 5/3~(지속진행)
B40: =+B39+1 -> 35 | C40: FLOW | D40: △ | E40: 공통 | F40: - | G40: ERP/MES | H40: OCA 오픈운영 | V40: 45049 | AB40: 준비 | AC40: 준비 | AD40: 운영진행
...

Sheet 선합지 일정
B1: ■ 선합지 구축 관련 일정
B2: 구분 | C2: 5월 | H2: 6월 | L2: 7월 | P2: 8월 | U2: 비고
C3: 1주차 | D3: 2주차 | E3: 3주차 | F3: 4주차 | G3: 5주차 | H3: 1주차 | I3: 2주차 | J3: 3주차 | K3: 4주차 | L3: 1주차 | M3: 2주차 | N3: 3주차 | O3: 4주차 | P3: 1주차 | Q3: 2주차 | R3: 3주차 | S3: 4주차 | T3: 5주차
B4: 선합지PLC연동개발 | R4: 조회
B5: AutoLami PLC연동테스트 | I5: ms콘퍼넌트
B6: EDI연동 API구축 | U6: *EDI 회원가입 및 협력사 Token발행 필수
B7: EDI연동 테스트 | U7: *연동데이터는 TEST데이터로 진행가능
B8: UTG수입검사 실적등록 | Q8: 조회
B9: 선합지 AutoLami 실적등록
B10: 선합지 AutoClave 실적등록
B11: 선합지 전수검사 | S11: 조회
B12: EDI CTQ등록
B13: 선합지 불량포장 | Q13: 조회
B14: 선합지 불량반품 | Q14: 조회
B15: 선합지 Rework
B16: SI-QC 검사 | S16: 조회
B17: 선합지 Pack재포장
B18: 선합지 QR마킹 | U18: *Marking설비업체 협업 진행
B19: 일반 QR마킹 | U19: *Marking설비업체 협업 진행
B20: 기타 선합지관련 조회화면 | Q20: 조회 | R20: 조회 | S20: 조회
B21: Direct T 연동테스트 | U21: *Direct T 관련 연동설정 필요
B22: 각 검사실적 연동
B23: 최종테스트 | R23: TEST | S23: TEST | T23: TEST

Sheet AOI일정표
B2: - 작업 예정 스케줄표
B3: 내용 | C3: 담당 | D3: 1 | E3: 2 | F3: 3 | G3: 4 | H3: 5 | I3: 6 | J3: 7 | K3: 8 | L3: 9 | M3: 10 | N3: 11 | O3: 12 | P3: 13 | Q3: 14 | R3: 15 | S3: 16 | T3: 17 | U3: 18 | V3: 19 | W3: 20 | X3: 21 | Y3: 22 | Z3: 23 | AA3: 24
B4: DB구축 | C4: 세경
B5: 접속TEST 진행 | C5: NEXT EYE
B6: 연동TES 자료송부 | C6: NEXT EYE
B7: TABLE구성 | C7: NEXT EYE
B8: 1차연동TEST | C8: 세경/ NEXT EYE
B9: TABLE수정 | C9: 세경/ NEXT EYE
B10: 2차연동TEST | C10: 세경/ NEXT EYE
B11: 화면구축 DATA확인 | C11: 세경
B12: 불량상세정보 연동TEST | C12: 세경/ NEXT EYE
B13: 이미지 저장 위치 설정 | C13: 세경
B14: 이미지 파일전송TEST | C14: 세경/ NEXT EYE
B15: 전산 PROCESS구축 | C15: 세경
B16: 조회화면 구축 | C16: 세경

Sheet OCA시범 운영
B2: 1. 3월 14일 기준
B3: 고객 | C3: 최종고객 | D3: 제품코드 | E3: ERP 코드 | F3: 현재상태
F4: 코드등록 | G4: BOM | H4: 라우팅 | I4: 자품목 | J4: 자재준비 | K4: 제조오더 | L4: 수주등록
B5: NITTO | C5: LGD | D5: 6302L-0144G | E5: PM02OC-2211-011 | F5: O | G5: 수정필요 | H5: 수정필요 | I5: 수정필요 | J5: X | K5: X | L5: X
B6: NITTO | C6: SDV | D6: LJ63-21457A | E6: PM02OC-2211-004 | F6: O | G6: 수정필요 | H6: 수정필요 | I6: 수정필요 | J6: X | K6: X | L6: X
B8: 2. 3월 15일 기준
B9: 고객 | C9: 최종고객 | D9: 제품코드 | E9: ERP 코드 | F9: 현재상태
F10: 코드등록 | G10: BOM | H10: 라우팅 | I10: 자품목 | J10: 자재준비 | K10: 제조오더 | L10: 수주등록
B11: NITTO | C11: LGD | D11: 6302L-0144G | E11: PM02OC-2211-011 | F11: O | G11: 일부수정필요 | H11: O | I11: 일부수정필요 | J11: X | K11: X | L11: X
B12: NITTO | C12: SDV | D12: LJ63-21457A | E12: PM02OC-2211-004 | F12: O | G12: 일부수정필요 | H12: O | I12: 일부수정필요 | J12: X | K12: X | L12: X
B14: 3. 3월 20일 기준
B15: 고객 | C15: 최종고객 | D15: 제품코드 | E15: ERP 코드 | F15: 현재상태
F16: 코드등록 | G16: BOM | H16: 라우팅 | I16: 자품목 | J16: 자재준비 | K16: 제조오더 | L16: 수주등록
B17: NITTO | C17: LGD | D17: 6302L-0144B | F17: X | G17: X | H17: X | I17: X | J17: X | K17: X | L17: X
B18: NITTO | C18: SDV | D18: LJ63-21457A | E18: PM02OC-2211-004 | F18: O | G18: 일부수정필요 | H18: O | I18: 일부수정필요 | J18: X | K18: X | L18: X
B19: * Roll / MT 단위에 대한 입력 현황 조정 필요
B21: 1. 현재 기준(0411)
B22: 고객 | C22: 최종고객 | D22: 제품코드 | E22: ERP 코드 | F22: 현재상태
F23: 코드등록 | G23: BOM | H23: 라우팅 | I23: 자품목 | J23: 자재준비 | K23: 제조오더 | L23: 수주등록 | M23: 라벨개발
B24: NITTO | C24: SDV | D24: LJ63-21457B | E24: PM02OC-2211-005 | F24: O | G24: O | H24: O | I24: O | J24: X | K24: X | L24: X | M24: X | N24: 생산미진행
B25: NITTO | C25: SDV | D25: LJ63-21457A | E25: PM02OC-2211-004 | F25: O | G25: O | H25: O | I25: O | J25: O | K25: O | L25: O | M25: X
B26: NITTO | C26: SDV | D26: LJ63-20877D | E26: PM02OC-2211-006 | F26: O | G26: O | H26: O | I26: O | J26: - | K26: - | L26: - | M26: X
B27: * 최종 코드 반영
B28: * 자재준비는 우선 기타입고로 반영 진행하여 생산 반영 진행 OR 정상 입고 진행 확인 진행
B30: ■ 진행 일정
B31: NO. | C31: 내용 | E31: 일정 | F31: 비고 | I31: 45008 | J31: =+I31+1 -> 45009 | K31: =+J31+1 -> 45010 | L31: =+K31+1 -> 45011 | M31: =+L31+1 -> 45012 | N31: =+M31+1 -> 45013 | O31: =+N31+1 -> 45014 | P31: =+O31+1 -> 45015 | Q31: =+P31+1 -> 45016 | ... V31: =+U31+1 -> 45021
B32: 1 | C32: BOM등록 교육 | E32: 45008 | F32: 오전(추가 문제있을 시 확인) 검증 프로세스에 대해 기준 필요 | I32: O
B33: =+B32+1 -> 2 | C33: BOM 재 등록 | E33: 45008 | F33: 오후 재등록 BOM확인 | I33: O | J33: O
B34: =+B33+1 -> 3 | C34: 사전simulation | E34: 3/24~ | F34: 미 개발 부분 외 문제점 확인 | J34: O | K34: O
B35: =+B34+1 -> 4 | C35: 전체코드 재등록? | E35: 진행여부 확인필요 | F35: BOM이후 확인 진행
B36: =+B35+1 -> 5 | C36: 전산등록 관련 교육 | F36: 실적 진행을 위한 추가 교육 | K36: O
B37: =+B36+1 -> 6 | C37: 금형등록 | E37: 45010 | F37: 1line 금형 등록 및 라벨 출력 | K37: 재교육진행 | M37: O
B38: =+B37+1 -> 7 | C38: 금형 interlock | F38: 금형관리를 통한 인터락기능 활성 | U38: TEST예정 | V38: O
B39: =+B38+1 -> 8 | C39: 자재준비 | E39: 3/23~3/27 | F39: 우선 기타입고 반영(MR기준) 구전산과 동시 진행 | K39: 재교육진행 | M39: O | O39: O
B40: =+B39+1 -> 9 | C40: 제조오더 | E40: 45009 | F40: 재 교육 완료 | M40: O
B41: =+B40+1 -> 10 | C41: 생산진행 | E41: 45012 | F41: 1LINE만 전산 동시 운영진행 | N41: O
B42: =+B41+1 -> 11 | C42: 수불부 교육 | E42: 45008 | F42: NITTO 활용관련 하여 교육진행 2회진행 | I42: O | K42: O
B43: =+B42+1 -> 12 | C43: 자재준비 | E43: 45010 | F43: 구매 발주부터 진행하여 반영(가상) | M43: O | N43: O | O43: O
B44: =+B43+1 -> 13 | C44: 라벨개발 | E44: - | F44: 일정 재확인 필요
B45: =+B44+1 -> 14 | C45: 추가문제점 확인 및 조치 | E45: 3/25~
...

Sheet PL시범 운영
B2: 1. 현재 기준(0411)
B3: 고객 | C3: 최종고객 | D3: 제품명 | E3: ERP CODE | F3: 현재상태
F4: 코드등록 | G4: BOM | H4: 라우팅 | I4: 자품목 | J4: 자재준비 | K4: 제조오더 | L4: 수주등록 | M4: 라벨개발
B5: SDV | C5: SDV | D5: LJ64-06562A | E5: PM04PL-2211-003 | F5: O | G5: O | H5: O | I5: O | J5: O | K5: O | L5: X | M5: X
D6: LJ64-06562A_Easy_LINER | E6: HM04PF-2211-001 | F6: O | G6: O | H6: O | I6: O | J6: O | K6: O | L6: - | M6: O | N6: 자재라벨 적용
D7: LJ64-06562A_Heavy_LINER | E7: HM04PF-2211-002 | F7: O | G7: O | H7: O | I7: O | J7: O | K7: O | L7: - | M7: O | N7: 자재라벨 적용
B8: * 최종 코드 반영 | M8: `
B9: * 자재준비는 우선 기타입고로 반영 진행하여 생산 반영 진행 OR 정상 입고 진행 확인 진행
B11: ■ 진행 일정
B12: NO. | C12: 내용 | E12: 일정 | F12: 비고 | I12: 45012 | J12: =+I12+1 -> 45013 | K12: =+J12+1 -> 45014 | L12: =+K12+1 -> 45015 | M12: =+L12+1 -> 45016 | N12: =+M12+1 -> 45017 | O12: =+N12+1 -> 45018 | P12: =+O12+1 -> 45019 | Q12: =+P12+1 -> 45020 | ... AK12: =+AJ12+1 -> 45040
B13: 1 | C13: BOM등록 교육 | E13: 3/24, 3/31 | F13: 다단계 구조 추가 교육진행 | M13: O
B14: =+B13+1 -> 2 | C14: BOM 재 등록 | E14: 3/31~ | F14: 재등록 BOM확인 | S14: O
B15: =+B14+1 -> 3 | C15: 라우팅 재교육 | E15: 45020 | F15: 변경된 PROCESS 기준 등록 교육
B16: =+B15+1 -> 4 | C16: 라우팅 재등록 | E16: 4/4~
B17: =+B16+1 -> 5 | C17: 사전simulation | E17: 3/24~ | F17: 미 개발 부분 외 문제점 확인
B18: =+B17+1 -> 6 | C18: 전산등록 관련 교육 | F18: 실적 진행을 위한 추가 교육 | M18: O
B19: =+B18+1 -> 7 | C19: 자재준비 | E19: 4/4~ | F19: 구전산과 동시 진행 | S19: O | T19: BOM변경으로 CODE 수정진행
B20: =+B19+1 -> 8 | C20: 제조오더 | E20: 45021 | F20: 재 교육 완료 | R20: O | S20: O | AA20: `
B21: =+B20+1 -> 9 | C21: 생산진행 | E21: 4/7~ | F21: 1품목 진행 | T21: O | U21: 실적 미진행 | W21: 재독려 필요 | Y21: O | Z21: O | AA21: O
B22: =+B21+1 -> 10 | C22: 조회화면 | E22: 확인중 | F22: 별도 개발 진행 필요(기간확인중)
B23: =+B22+1 -> 11 | C23: 자재준비 | E23: 4/4~ | F23: 구매 발주부터 진행하여 반영(가상) | Q23: O | R23: O | S23: O | T23: O
B24: =+B23+1 -> 12 | C24: 라벨개발 | F24: 일정 재확인 필요
B25: =+B24+1 -> 13 | C25: 추가문제점 확인 및 조치 | E25: 4/6~
B26: =+B25+1 -> 14 | C26: 실 재고 반영 | E26: 3/31~4/1 | F26: 재고조사 기준 반영
B27: =+B26+1 -> 15 | C27: 추가 코드 점진적 진행 | E27: 4/12~

Sheet SUS시범 운영 
B2: 1. 현재 기준(0411)
B3: 고객 | C3: 최종고객 | D3: 제품CODE | E3: ERP CODE | F3: 현재상태
F4: 코드등록 | G4: BOM | H4: 라우팅 | I4: 자품목 | J4: 자재준비 | K4: 제조오더 | L4: 수주등록 | M4: 라벨개발
B5: LGDISPLAY | C5: LGDISPLAY | D5: 3300L-0808B | E5: PM01CA-2211-167 | F5: O | G5: O | H5: O | I5: O
D6: TOP DJ 3300L-0808B | E6: HM01CA-2211-001 | F6: O | G6: O | H6: O | I6: O | M6: O | N6: 자재라벨 적용
D7: BTM DJ 3300L-0808B | E7: HM01CA-2211-002 | F7: O | G7: O | H7: O | I7: O | M7: O | N7: 자재라벨 적용
B8: * 최종 코드 반영 | M8: `
B9: * 자재준비는 우선 기타입고로 반영 진행하여 생산 반영 진행 OR 정상 입고 진행 확인 진행
B11: ■ 진행 일정
B12: NO. | C12: 내용 | E12: 일정 | F12: 비고 | I12: 45023 | J12: =+I12+1 -> 45024 | K12: =+J12+1 -> 45025 | L12: =+K12+1 -> 45026 | M12: =+L12+1 -> 45027 | N12: =+M12+1 -> 45028 | O12: =+N12+1 -> 45029 | P12: =+O12+1 -> 45030 | Q12: =+P12+1 -> 45031 | ... Y12: =+X12+1 -> 45039
B13: 1 | C13: BOM등록 교육 | F13: 다단계 구조 추가 교육진행 | J13: o
B14: =+B13+1 -> 2 | C14: BOM 재 등록 | F14: 재등록 BOM확인 | J14: o
B15: =+B14+1 -> 3 | C15: 라우팅 재등록 | L15: o
B16: =+B15+1 -> 4 | C16: 사전simulation | F16: 미 개발 부분 외 문제점 확인 | M16: o
B17: =+B16+1 -> 5 | C17: 전산등록 관련 교육 | F17: 실적 진행을 위한 추가 교육
B18: =+B17+1 -> 6 | C18: 자재준비 | F18: 구전산과 동시 진행 | O18: o | P18: o
B19: =+B18+1 -> 7 | C19: 제조오더 | F19: 재 교육 완료
B20: =+B19+1 -> 8 | C20: 생산진행 | F20: 1품목 진행
B21: =+B20+1 -> 9 | C21: 조회화면 | F21: 별도 개발 진행 필요(기간확인중)
B22: =+B21+1 -> 10 | C22: 자재준비 | F22: 구매 발주부터 진행하여 반영(가상)
B23: =+B22+1 -> 11 | C23: 라벨개발 | F23: 일정 재확인 필요
B24: =+B23+1 -> 12 | C24: 추가문제점 확인 및 조치
B25: =+B24+1 -> 13 | C25: 실 재고 반영 | F25: 재고조사 기준 반영
B26: =+B25+1 -> 14 | C26: 추가 코드 점진적 진행

Sheet DECO시범 운영
B2: 1. 현재 기준(0411)
B3: 고객 | C3: 최종고객 | D3: 제품CODE | E3: ERP CODE | F3: 현재상태
F4: 코드등록 | G4: BOM | H4: 라우팅 | I4: 자품목 | J4: 자재준비 | K4: 제조오더 | L4: 수주등록 | M4: 라벨개발
B5: SDV | C5: SDV | D5: 520 GREEN
N6: 자재라벨 적용
N7: 자재라벨 적용
B8: * 최종 코드 반영 | M8: `
B9: * 자재준비는 우선 기타입고로 반영 진행하여 생산 반영 진행 OR 정상 입고 진행 확인 진행
B10: * 반제품화 진행여부는 확인 필요
B11: ■ 진행 일정
B12: NO. | C12: 내용 | E12: 일정 | F12: 비고 | I12: 45023 | J12: =+I12+1 -> 45024 | K12: =+J12+1 -> 45025 | L12: =+K12+1 -> 45026 | M12: =+L12+1 -> 45027 | N12: =+M12+1 -> 45028 | O12: =+N12+1 -> 45029 | P12: =+O12+1 -> 45030 | Q12: =+P12+1 -> 45031 | ... Y12: =+X12+1 -> 45039
B13: 1 | C13: 구매교육(CODE~발주) | F13: 변경된 PROCESS 기준 등록 교육 | J13: O | Q13: O
B14: =+B13+1 -> 2 | C14: BOM등록 교육 | E14: 45027 | F14: 다단계 구조 추가 교육진행 | M14: O | Q14: O
B15: =+B14+1 -> 3 | C15: BOM 재 등록 | E15: ~4/13 | F15: 재등록 BOM확인 | O15: O
B16: =+B15+1 -> 4 | C16: 라우팅/생산 재교육 | E16: 45028 | F16: 변경된 PROCESS 기준 등록 교육 | S16: O
B17: =+B16+1 -> 5 | C17: 라우팅 재등록 | E17: ~4/13 | T17: O
B18: =+B17+1 -> 6 | C18: 사전simulation | E18: ~4/13 | F18: 미 개발 부분 외 문제점 확인 | O18: O
B19: =+B18+1 -> 7 | C19: 전산등록 관련 교육 | E19: 45028 | F19: 기존 내용 점검 | O19: O
B20: =+B19+1 -> 8 | C20: 자재준비 | E20: ~4/15 | F20: 구 전산과 동시 진행 라벨 라인투입진행 | W20: O
B21: =+B20+1 -> 9 | C21: 제조오더 | E21: 45029
B22: =+B21+1 -> 10 | C22: 생산진행 | E22: 4/17~ | F22: 1품목 진행
B23: =+B22+1 -> 11 | C23: 조회화면 | E23: - | F23: 별도 개발 진행 필요(기간확인중)
B24: =+B23+1 -> 12 | C24: 라벨개발 | E24: - | F24: 일정 재확인 필요
B25: =+B24+1 -> 13 | C25: 추가문제점 확인 및 조치 | E25: -
B26: =+B25+1 -> 14 | C26: 실 재고 반영 | E26: 5월초 반영 | F26: 재고조사 기준 반영
B27: =+B26+1 -> 15 | C27: 추가 코드 점진적 진행 | E27: 운영 DB RESET 후 진행
